

<mujoco>
    <option gravity="0 0 0" />
    <asset>
        <material name="green" rgba="0 1 0 1" />
        <texture name="grid" type="2d" builtin="checker" width="512" height="512" rgb1=".1 .2 .3" rgb2=".2 .3 .4" />
        <material name="grid" texture="grid" texrepeat="1 1" texuniform="true" reflectance=".2" />
    </asset>

    <worldbody>
        <light diffuse="0.3 0.3 0.3" pos="1 0 3" dir="-1 0 -3" />
        <geom type="plane" size="10 10 0.1"  material="grid" />

        <body pos="0 0 2" euler="0 180 0">
            <joint name="joint1" type="hinge" axis="0 -1 0" pos="0 0 0.5" />
            <geom type="cylinder" size="0.05 0.5" mass="1" material="green" />
        </body>
    </worldbody>

    <actuator>
        <position name="pos_ctrl1" joint="joint1" kp="10" />
        <velocity name="vel_ctrl1" joint="joint1" kv="1" />
        <motor name="trq_ctrl1" joint="joint1" ctrllimited="true" ctrlrange="-100 100" />
    </actuator>


    <sensor>
        <jointpos name="pos_sensor1" joint="joint1" />
        <jointvel name="vel_sensor1" joint="joint1" />
    </sensor>

</mujoco>
